<?xml version="1.0" encoding="UTF-8"?>
<testsuite name="Admin - Simulation - Personnel - Add/Edit/Delete/ErrorCheck"
           tests="1"
           failures="1"
           errors="0"
           skipped="0"
           time="37.861">
  <properties />
            <testcase name="execute" time="37.861" classname="testCases.Admin.Simulation.PersonnelAddEditDelete">
                <failure type="java.lang.AssertionError"
                  message="Errors - Personnel Already Exists expected [Personnel already exists.] but found []"
              >
<![CDATA[java.lang.AssertionError: Errors - Personnel Already Exists expected [Personnel already exists.] but found []
  org.testng.Assert.fail(Assert.java:93)
  org.testng.Assert.failNotEquals(Assert.java:512)
  org.testng.Assert.assertEqualsImpl(Assert.java:134)
  org.testng.Assert.assertEquals(Assert.java:115)
  org.testng.Assert.assertEquals(Assert.java:189)
  testCases.Admin.Simulation.PersonnelAddEditDelete.performErrorValidation(PersonnelAddEditDelete.java:202)
  testCases.Admin.Simulation.PersonnelAddEditDelete.execute(PersonnelAddEditDelete.java:91)
  sun.reflect.NativeMethodAccessorImpl.invoke0(Native Method)
  sun.reflect.NativeMethodAccessorImpl.invoke(Unknown Source)
  sun.reflect.DelegatingMethodAccessorImpl.invoke(Unknown Source)
  java.lang.reflect.Method.invoke(Unknown Source)
  org.testng.internal.MethodInvocationHelper.invokeMethod(MethodInvocationHelper.java:108)
  org.testng.internal.Invoker.invokeMethod(Invoker.java:661)
  org.testng.internal.Invoker.invokeTestMethod(Invoker.java:869)
  org.testng.internal.Invoker.invokeTestMethods(Invoker.java:1193)
  org.testng.internal.TestMethodWorker.invokeTestMethods(TestMethodWorker.java:126)
  org.testng.internal.TestMethodWorker.run(TestMethodWorker.java:109)
  java.util.concurrent.ThreadPoolExecutor.runWorker(Unknown Source)
  java.util.concurrent.ThreadPoolExecutor$Worker.run(Unknown Source)
  java.lang.Thread.run(Unknown Source)
]]>
      </failure>

          </testcase>
  
  
  
</testsuite>
